
<robot name="phantom">

    <!--LINKS-->

    <link name="Box">
        <inertial>
            <mass value="5"/>
            <origin xyz="0 0 0" rpy="0 0 0" />
            <inertia ixx="0.027604" iyy="0.011288" izz="0.031195" ixy="0" ixz="0" iyz="0"/>
        </inertial>

        <visual>
            <origin xyz="0 0 0" rpy="0 0 0" />
            <geometry>
                <box size="0.13409     0.23961    0.096443"/>
            </geometry>
            <material name="white">
            <color rgba="1 1 1 1"/>
            </material>
        </visual>
    </link>

    <link name="RightUp_f1">
        <inertial>
            <mass value="0.0001"/>
            <origin xyz="0 0 0" rpy="0 0 0" />
            <inertia ixx="0.0003" iyy="0.0003" izz="0.0003" ixy="0" ixz="0" iyz="0"/>
        </inertial>
    </link>
    <link name="RightUp_f2">
        <inertial>
            <mass value="0.0001"/>
            <origin xyz="0 0 0" rpy="0 0 0" />
            <inertia ixx="0.0003" iyy="0.0003" izz="0.0003" ixy="0" ixz="0" iyz="0"/>
        </inertial>
    </link>
    <link name="RightUp">
        <inertial>
            <mass value="7.7581"/>
            <origin xyz="0           0    -0.20463" rpy="0 0 0" />
            <inertia ixx="0.11345" iyy="0.11345" izz="0.010326" ixy="0" ixz="0" iyz="0"/>
        </inertial>

        <visual>
            <origin xyz="0           0    -0.20463" rpy="0 0 0" />
            <geometry>
                <cylinder length="0.40926" radius="0.051595"/>
            </geometry>
            <material name="white">
                <color rgba="1 1 1 1"/>
            </material>
        </visual>
    </link>

    <link name="RightLow_f1">
        <inertial>
            <mass value="0.0001"/>
            <origin xyz="0 0 0" rpy="0 0 0" />
            <inertia ixx="0.0003" iyy="0.0003" izz="0.0003" ixy="0" ixz="0" iyz="0"/>
        </inertial>
    </link>
    <link name="RightLow">
        <inertial>
            <mass value="2.2654"/>
            <origin xyz="0           0    -0.21406" rpy="0 0 0" />
            <inertia ixx="0.035474" iyy="0.035474" izz="0.0017488" ixy="0" ixz="0" iyz="0"/>
        </inertial>

        <visual>
            <origin xyz="0           0    -0.21406" rpy="0 0 0" />
            <geometry>
                <cylinder length="0.42811" radius="0.039293"/>
            </geometry>
            <material name="white">
                <color rgba="1 1 1 1"/>
            </material>
        </visual>
    </link>

    <link name="RightShoe_f1">
        <inertial>
            <mass value="0.0001"/>
            <origin xyz="0 0 0" rpy="0 0 0" />
            <inertia ixx="0.0003" iyy="0.0003" izz="0.0003" ixy="0" ixz="0" iyz="0"/>
        </inertial>
    </link>
    <link name="RightShoe_f2">
        <inertial>
            <mass value="0.0001"/>
            <origin xyz="0 0 0" rpy="0 0 0" />
            <inertia ixx="0.0003" iyy="0.0003" izz="0.0003" ixy="0" ixz="0" iyz="0"/>
        </inertial>
    </link>
    <link name="RightShoe">
        <inertial>
            <mass value="0.80684"/>
            <origin xyz="0.047341           0   -0.045923" rpy="0 0 0" />
            <inertia ixx="0.00098245" iyy="0.0025999" izz="0.0024479" ixy="0" ixz="0" iyz="0"/>
        </inertial>

        <visual>
            <origin xyz="0.047341           0   -0.045923" rpy="0 0 0" />
            <geometry>
                <box size="0.17387    0.078587    0.091847"/>
            </geometry>
            <material name="white">
                <color rgba="1 1 1 1"/>
            </material>
        </visual>
    </link>

    <link name="LeftUp_f1">
        <inertial>
            <mass value="0.0001"/>
            <origin xyz="0 0 0" rpy="0 0 0" />
            <inertia ixx="0.0003" iyy="0.0003" izz="0.0003" ixy="0" ixz="0" iyz="0"/>
        </inertial>
    </link>
    <link name="LeftUp_f2">
        <inertial>
            <mass value="0.0001"/>
            <origin xyz="0 0 0" rpy="0 0 0" />
            <inertia ixx="0.0003" iyy="0.0003" izz="0.0003" ixy="0" ixz="0" iyz="0"/>
        </inertial>
    </link>
    <link name="LeftUp">
        <inertial>
            <mass value="7.7581"/>
            <origin xyz="0           0    -0.20463" rpy="0 0 0" />
            <inertia ixx="0.11345" iyy="0.11345" izz="0.010326" ixy="0" ixz="0" iyz="0"/>
        </inertial>

        <visual>
            <origin xyz="0           0    -0.20463" rpy="0 0 0" />
            <geometry>
                <cylinder length="0.40926" radius="-0.051595"/>
            </geometry>
            <material name="white">
                <color rgba="1 1 1 1"/>
            </material>
        </visual>
    </link>

    <link name="LeftLow_f1">
        <inertial>
            <mass value="0.0001"/>
            <origin xyz="0 0 0" rpy="0 0 0" />
            <inertia ixx="0.0003" iyy="0.0003" izz="0.0003" ixy="0" ixz="0" iyz="0"/>
        </inertial>
    </link>
    <link name="LeftLow">
        <inertial>
            <mass value="2.2654"/>
            <origin xyz="0           0    -0.21406" rpy="0 0 0" />
            <inertia ixx="0.035474" iyy="0.035474" izz="0.0017488" ixy="0" ixz="0" iyz="0"/>
        </inertial>

        <visual>
            <origin xyz="0           0    -0.21406" rpy="0 0 0" />
            <geometry>
                <cylinder length="0.42811" radius="0.039293"/>
            </geometry>
            <material name="white">
                <color rgba="1 1 1 1"/>
            </material>
        </visual>
    </link>

    <link name="LeftShoe_f1">
        <inertial>
            <mass value="0.0001"/>
            <origin xyz="0 0 0" rpy="0 0 0" />
            <inertia ixx="0.0003" iyy="0.0003" izz="0.0003" ixy="0" ixz="0" iyz="0"/>
        </inertial>
    </link>
    <link name="LeftShoe_f2">
        <inertial>
            <mass value="0.0001"/>
            <origin xyz="0 0 0" rpy="0 0 0" />
            <inertia ixx="0.0003" iyy="0.0003" izz="0.0003" ixy="0" ixz="0" iyz="0"/>
        </inertial>
    </link>
    <link name="LeftShoe">
        <inertial>
            <mass value="0.80684"/>
            <origin xyz="0.047341           0   -0.045923" rpy="0 0 0" />
            <inertia ixx="0.00098245" iyy="0.0025999" izz="0.0024479" ixy="0" ixz="0" iyz="0"/>
        </inertial>

        <visual>
            <origin xyz="0.047341           0   -0.045923" rpy="0 0 0" />
            <geometry>
                <box size="0.17387    0.078587    0.091847"/>
            </geometry>
            <material name="white">
                <color rgba="1 1 1 1"/>
            </material>
        </visual>
    </link>

    <!--JOINTS-->
    <joint name="RightRotHip_x" type="revolute">
        <origin xyz="3.7e-05   -0.079215    0.000367" rpy="0 0 0"/>
        <parent link="Box"/>
        <child link="RightUp_f1"/>
        <dynamics damping="0.1" friction="0.0"/>
        <limit effort="30" velocity="1.0" lower="-0.523599" upper="0.785398" />
        <axis xyz="1 0 0" />
    </joint>
    <joint name="RightRotHip_y" type="revolute">
        <origin xyz="0 0 0" rpy="0 0 0"/>
        <parent link="RightUp_f1"/>
        <child link="RightUp_f2"/>
        <dynamics damping="0.1" friction="0.0"/>
        <limit effort="30" velocity="1.0" lower="-0.261799" upper="2.0944" />
        <axis xyz="0 1 0" />
    </joint>
    <joint name="RightRotHip_z" type="revolute">
        <origin xyz="0 0 0" rpy="0 0 0"/>
        <parent link="RightUp_f2"/>
        <child link="RightUp"/>
        <dynamics damping="0.1" friction="0.0"/>
        <limit effort="30" velocity="1.0" lower="-0.785398" upper="0.785398" />
        <axis xyz="0 0 1" />
    </joint>
    <joint name="RightRotKnee_y" type="revolute">
        <origin xyz="-2e-06           0    -0.40926" rpy="0 0 0"/>
        <parent link="RightUp"/>
        <child link="RightLow_f1"/>
        <dynamics damping="0.1" friction="0.0"/>
        <limit effort="30" velocity="1.0" lower="0" upper="2.35619" />
        <axis xyz="0 1 0" />
    </joint>
    <joint name="RightRotKnee_z" type="revolute">
        <origin xyz="0 0 0" rpy="0 0 0"/>
        <parent link="RightLow_f1"/>
        <child link="RightLow"/>
        <dynamics damping="0.1" friction="0.0"/>
        <limit effort="30" velocity="1.0" lower="-0.698132" upper="0.523599" />
        <axis xyz="0 0 1" />
    </joint>
    <joint name="RightRotAnkle_x" type="revolute">
        <origin xyz="-0.000373           0    -0.42811" rpy="0 0 0"/>
        <parent link="RightLow"/>
        <child link="RightShoe_f1"/>
        <dynamics damping="0.1" friction="0.0"/>
        <limit effort="30" velocity="1.0" lower="-0.610865" upper="0.785398" />
        <axis xyz="1 0 0" />
    </joint>
    <joint name="RightRotAnkle_y" type="revolute">
        <origin xyz="0 0 0" rpy="0 0 0"/>
        <parent link="RightShoe_f1"/>
        <child link="RightShoe_f2"/>
        <dynamics damping="0.1" friction="0.0"/>
        <limit effort="30" velocity="1.0" lower="-0.523599" upper="0.872665" />
        <axis xyz="0 1 0" />
    </joint>
    <joint name="RightRotAnkle_z" type="revolute">
        <origin xyz="0 0 0" rpy="0 0 0"/>
        <parent link="RightShoe_f2"/>
        <child link="RightShoe"/>
        <dynamics damping="0.1" friction="0.0"/>
        <limit effort="30" velocity="1.0" lower="-0.436332" upper="0.872665" />
        <axis xyz="0 0 1" />
    </joint>

    <joint name="LeftRotHip_x" type="revolute">
        <origin xyz="3.7e-05    0.079215    0.000367" rpy="0 0 0"/>
        <parent link="Box"/>
        <child link="LeftUp_f1"/>
        <dynamics damping="0.1" friction="0.0"/>
        <limit effort="30" velocity="1.0" lower="-0.523599" upper="0.785398" />
        <axis xyz="1 0 0" />
    </joint>
    <joint name="LeftRotHip_y" type="revolute">
        <origin xyz="0 0 0" rpy="0 0 0"/>
        <parent link="LeftUp_f1"/>
        <child link="LeftUp_f2"/>
        <dynamics damping="0.1" friction="0.0"/>
        <limit effort="30" velocity="1.0" lower="-0.261799" upper="2.0944" />
        <axis xyz="0 1 0" />
    </joint>
    <joint name="LeftRotHip_z" type="revolute">
        <origin xyz="0 0 0" rpy="0 0 0"/>
        <parent link="LeftUp_f2"/>
        <child link="LeftUp"/>
        <dynamics damping="0.1" friction="0.0"/>
        <limit effort="30" velocity="1.0" lower="-0.785398" upper="0.785398" />
        <axis xyz="0 0 1" />
    </joint>
    <joint name="LeftRotKnee_y" type="revolute">
        <origin xyz="-2e-06           0    -0.40926" rpy="0 0 0"/>
        <parent link="LeftUp"/>
        <child link="LeftLow_f1"/>
        <dynamics damping="0.1" friction="0.0"/>
        <limit effort="30" velocity="1.0" lower="0" upper="2.35619" />
        <axis xyz="0 1 0" />
    </joint>
    <joint name="LeftRotKnee_z" type="revolute">
        <origin xyz="0 0 0" rpy="0 0 0"/>
        <parent link="LeftLow_f1"/>
        <child link="LeftLow"/>
        <dynamics damping="0.1" friction="0.0"/>
        <limit effort="30" velocity="1.0" lower="-0.523599" upper="0.698132" />
        <axis xyz="0 0 1" />
    </joint>
    <joint name="LeftRotAnkle_x" type="revolute">
        <origin xyz="-0.000373           0    -0.42811" rpy="0 0 0"/>
        <parent link="LeftLow"/>
        <child link="LeftShoe_f1"/>
        <dynamics damping="0.1" friction="0.0"/>
        <limit effort="30" velocity="1.0" lower="-0.610865" upper="0.785398" />
        <axis xyz="1 0 0" />
    </joint>
    <joint name="LeftRotAnkle_y" type="revolute">
        <origin xyz="0 0 0" rpy="0 0 0"/>
        <parent link="LeftShoe_f1"/>
        <child link="LeftShoe_f2"/>
        <dynamics damping="0.1" friction="0.0"/>
        <limit effort="30" velocity="1.0" lower="-0.523599" upper="0.872665" />
        <axis xyz="0 1 0" />
    </joint>
    <joint name="LeftRotAnkle_z" type="revolute">
        <origin xyz="0 0 0" rpy="0 0 0"/>
        <parent link="LeftShoe_f2"/>
        <child link="LeftShoe"/>
        <dynamics damping="0.1" friction="0.0"/>
        <limit effort="30" velocity="1.0" lower="-0.872665" upper="0.436332" />
        <axis xyz="0 0 1" />
    </joint>-->

</robot>




